#VRML_SIM R2021a utf8
WorldInfo {
  basicTimeStep 8
  coordinateSystem "NUE"
}
Viewpoint {
  orientation -0.11436501525142803 -0.9893280906976006 -0.0902805197325579 1.4118118109104316
  position -1.211448011576095 0.40761339829848625 0.017886660425423168
}
TexturedBackground {
}
TexturedBackgroundLight {
}
Floor {
  size 1 2
}
Solid {
  translation 0.55 0.05 0
  children [
    DEF BOX_GEOMETRY Shape {
      appearance PBRAppearance {
        baseColor 0.3 0.2 0.2
        roughness 1
        metalness 0.05
      }
      geometry Box {
        size 0.1 0.1 1
      }
    }
  ]
  name "solid(2)"
  boundingObject USE BOX_GEOMETRY
}
Solid {
  translation -5.60782e-07 0.05 -0.55
  rotation 0 1 0 -1.5707953071795862
  children [
    USE BOX_GEOMETRY
  ]
  name "solid(3)"
  boundingObject USE BOX_GEOMETRY
}
Solid {
  translation 0.255175 0.0306814 -0.79
  rotation -0.12942794302188446 0.9831055672070398 -0.12942894302144423 -1.5878353071795859
  children [
    DEF Ramp Shape {
      appearance PBRAppearance {
        baseColor 0.1 0.1 0.1
        roughness 1
        metalness 0.2
      }
      geometry Box {
        size 0.3 0.01 0.3
      }
    }
  ]
  name "solid(6)"
  boundingObject USE Ramp
}
Solid {
  translation -0.55 0.05 5.58265e-07
  rotation 0 1 0 1.01503e-06
  children [
    USE BOX_GEOMETRY
  ]
  name "solid(4)"
  boundingObject USE BOX_GEOMETRY
}
Solid {
  translation 5.60792e-07 0.05 0.55
  rotation 0 1 0 -1.5707953071795862
  children [
    USE BOX_GEOMETRY
  ]
  name "solid(5)"
  boundingObject USE BOX_GEOMETRY
}
DEF four__wheel Robot {
  translation 0.67 0.04 0
  children [
    DEF BODY Shape {
      appearance PBRAppearance {
        baseColor 1 0 0
        metalness 0
      }
      geometry Box {
        size 0.1 0.05 0.2
      }
    }
    HingeJoint {
      jointParameters HingeJointParameters {
        anchor 0.06 0 0.05
      }
      device [
        RotationalMotor {
          name "wheel1"
        }
      ]
      endPoint DEF WHEEL1 Solid {
        translation 0.06 0 0.05
        rotation 1.2517116859047111e-10 -1.251716283706907e-10 1 1.5708
        children [
          DEF WHEEL Shape {
            appearance PBRAppearance {
              baseColor 0 1 0
              transparency 0.1
              roughness 1
              metalness 0.1
            }
            geometry Cylinder {
              height 0.02
              radius 0.04
            }
          }
        ]
        boundingObject USE WHEEL
        physics DEF WHEEL_PH Physics {
        }
      }
    }
    HingeJoint {
      jointParameters HingeJointParameters {
        anchor -0.06 0 0.05
      }
      device [
        RotationalMotor {
          name "wheel2"
        }
      ]
      endPoint DEF WHEEL_2 Solid {
        translation -0.06 0 0.05
        rotation 1.2517076243323637e-10 -1.2517122221196404e-10 1 1.5708
        children [
          USE WHEEL
        ]
        name "solid(1)"
        boundingObject USE WHEEL
        physics USE WHEEL_PH
      }
    }
    HingeJoint {
      jointParameters HingeJointParameters {
        anchor 0.06 0 -0.05
      }
      device [
        RotationalMotor {
          name "wheel3"
        }
      ]
      endPoint DEF WHEEL_3 Solid {
        translation 0.06 0 -0.05
        rotation -1.2516341950922544e-10 1.251638792609811e-10 1 1.5708
        children [
          USE WHEEL
        ]
        name "solid(2)"
        boundingObject USE WHEEL
        physics USE WHEEL_PH
      }
    }
    HingeJoint {
      jointParameters HingeJointParameters {
        anchor -0.06 0 -0.05
      }
      device [
        RotationalMotor {
          name "wheel4"
        }
      ]
      endPoint DEF WHEEL_4 Solid {
        translation -0.06 0 -0.05
        rotation -1.2515744181086859e-10 1.2515790154066702e-10 1 1.5708
        children [
          USE WHEEL
        ]
        name "solid(3)"
        boundingObject USE WHEEL
        physics USE WHEEL_PH
      }
    }
    DistanceSensor {
      translation 0.03 0 0.1
      rotation 0 -1 0 1.309
      children [
        DEF SENSOR_GEOM Shape {
          appearance PBRAppearance {
          }
          geometry Box {
            size 0.01 0.01 0.01
          }
        }
      ]
      name "ds_left"
    }
    DistanceSensor {
      translation -0.03 0 0.1
      rotation 0 1 0 -1.8325953071795862
      children [
        DEF SENSOR_GEOM Shape {
          appearance PBRAppearance {
          }
          geometry Box {
            size 0.01 0.01 0.01
          }
        }
      ]
      name "ds_right"
    }
  ]
  boundingObject USE BODY
  physics Physics {
  }
  controller "4_wheel_robot"
}
DEF Launcher_robot Robot {
  translation 0 0.025 -0.09
  children [
    SliderJoint {
      jointParameters JointParameters {
        axis 0 1 0
        minStop -0.03
        maxStop 0.25
        springConstant 500
      }
      device [
        LinearMotor {
          name "spring_motor"
          minPosition -0.03
          maxPosition 0.25
          maxForce 25
        }
      ]
      endPoint Solid {
        translation 3.627200297787333e-19 0.06 4.0068381956374637e-19
        rotation 0.021447128559780933 0.9992743609925998 -0.03147653315363493 -5.257062957556269e-17
        children [
          BallJoint {
            jointParameters DEF tether_joint_params BallJointParameters {
              position 0.3
              minStop -1.57
              maxStop 1.57
            }
            endPoint Solid {
              rotation 0.9999999551904559 -0.0002960072213053016 -4.470806710857097e-05 0.3001500856954891
              children [
                DEF tether_endpoint Shape {
                  geometry Sphere {
                    radius 0.003
                  }
                }
                SliderJoint {
                  jointParameters JointParameters {
                    position 0.36
                    axis 0 1 0
                    minStop 0.015
                    maxStop 1
                    springConstant 5
                    dampingConstant 1
                  }
                  device [
                    LinearMotor {
                      name "tether_motor"
                      minPosition 0.015
                      maxPosition 1
                    }
                  ]
                  endPoint Solid {
                    translation 0 0.345 0
                    children [
                      USE tether_endpoint
                      BallJoint {
                        jointParameters BallJointParameters {
                          position -0.3
                          minStop -1.57
                          maxStop 1.57
                        }
                        endPoint Solid {
                          translation -2.5387368481948706e-10 0.014330405983770646 -0.0044317217612213754
                          rotation -0.9999997130873021 -0.0007490023662541027 0.00011322883427153844 0.2999241495673711
                          children [
                            Connector {
                              translation 0 0.015 0
                              rotation 1 0 0 -1.5707953071795862
                              model "magnetic"
                              autoLock TRUE
                              axisTolerance 3.14
                              rotationTolerance 3.14
                              numberOfRotations 0
                            }
                            DEF Cylinder_proj Shape {
                              appearance PBRAppearance {
                                baseColor 0.3 0.3 1
                                metalness 0.5
                              }
                              geometry Cylinder {
                                height 0.03
                                radius 0.025
                              }
                            }
                          ]
                          boundingObject USE Cylinder_proj
                          physics Physics {
                            density 10
                          }
                        }
                      }
                    ]
                    boundingObject USE tether_endpoint
                    physics Physics {
                      density -1
                      mass 0.005
                    }
                  }
                }
              ]
              name "solid(1)"
              boundingObject USE tether_endpoint
              physics Physics {
                density -1
                mass 0.005
              }
            }
          }
          DEF Launchpad Shape {
            appearance PBRAppearance {
              baseColor 1 0 0
            }
            geometry Box {
              size 0.1 0.005 0.1
            }
          }
        ]
        boundingObject USE Launchpad
        physics Physics {
          density -1
          mass 0.01
        }
      }
    }
    USE BODY
  ]
  name "robot(1)"
  boundingObject USE BODY
  physics Physics {
    density 100
  }
  controller "launcher"
}
DEF Projectile_robot Robot {
  translation 0.37 0.11 -0.43
  children [
    Connector {
      model "magnetic"
      isLocked TRUE
      autoLock TRUE
      axisTolerance 3.14
      rotationTolerance 3.14
    }
    DEF Projectile_attachable Shape {
      appearance PBRAppearance {
      }
      geometry Sphere {
        radius 0.02
        subdivision 2
      }
    }
  ]
  name "robot(2)"
  boundingObject USE Projectile_attachable
  physics Physics {
    density -1
    mass 0.001
  }
  controller "projectile_controller"
}
DEF Roof_robot Robot {
  translation 0 0.41 0
  children [
    DEF roof_shape Shape {
      appearance PBRAppearance {
        baseColor 1 0.8 0.8
      }
      geometry Box {
        size 0.6 0.01 0.6
      }
    }
    Connector {
      translation 0 -0.005 0
      rotation -1 0 0 -1.5707953071795862
      model "magnetic"
      autoLock TRUE
      axisTolerance 3.14
      rotationTolerance 3.14
      numberOfRotations 0
    }
  ]
  name "robot(3)"
  boundingObject USE roof_shape
  controller "projectile_controller"
}
Robot {
  translation 0.15 0.03 -0.74
  rotation 1 0 0 1.5708
  children [
    Connector {
      translation 0 0.025 0
      model "magnetic"
      autoLock TRUE
      axisTolerance 3.14
      rotationTolerance 3.14
    }
    DEF Cylinder_shape Shape {
      appearance PBRAppearance {
        baseColor 0.5 1 0.5
        metalness 0.5
      }
      geometry Cylinder {
        height 0.05
        radius 0.02
      }
    }
  ]
  name "robot(4)"
  boundingObject USE Cylinder_shape
  physics Physics {
  }
  controller "projectile_controller"
}
Robot {
  translation 0.11 0.02 -0.69
  rotation 1 0 0 -1.5707953071795862
  children [
    Connector {
      translation 0 0.025 0
      model "magnetic"
      autoLock TRUE
      axisTolerance 3.14
      rotationTolerance 3.14
    }
    DEF Cylinder_shape Shape {
      appearance PBRAppearance {
        baseColor 0.5 1 0.5
        metalness 0.5
      }
      geometry Cylinder {
        height 0.05
        radius 0.02
      }
    }
  ]
  name "robot(5)"
  boundingObject USE Cylinder_shape
  physics Physics {
  }
  controller "projectile_controller"
}
Robot {
  translation 0 0.14 0.38
  rotation -1 0 0 -5.307179586466759e-06
  children [
    Connector {
      translation 0 0.025 0
      rotation 1 0 0 -1.5707953071795862
      model "magnetic"
      autoLock TRUE
      axisTolerance 3.14
      rotationTolerance 3.14
      numberOfRotations 0
    }
    DEF Cylinder_shape Shape {
      appearance PBRAppearance {
        baseColor 0.5 1 0.5
        metalness 0.5
      }
      geometry Cylinder {
        height 0.05
        radius 0.02
      }
    }
  ]
  name "robot(6)"
  boundingObject USE Cylinder_shape
  physics Physics {
    density 100
  }
  controller "projectile_controller"
}
